Workbook

Sheet Data
A1: =COUNTA(A3:A811) -> 331
A2: Guest Name | B2: Booking Dates | C2: Folio No | D2: Email | E2: xx | F2: Service | G2: Food | H2: Activities | I2: Lodge Staff | J2: Accommodation | K2: Overall Stay | L2: Comments
A4: SVETLANA VENKOVA | B4: MARCH | D4: tretinskai@yandex.ru | F4: EXCELLENT | G4: EXCELLENT | H4: EXCELLENT | I4: EXCELLENT | J4: EXCELLENT | K4: EXCELLENT
A5: DMITRY VENKOV | B5: MARCH | D5: dmitryvenkov@yandex.ry | F5: EXCELLENT | G5: EXCELLENT | H5: EXCELLENT | I5: EXCELLENT | J5: EXCELLENT | K5: EXCELLENT | L5: THANK YOU VERY MUCH FOR THESE DAYS TOGETHER WITH YOU.
A6: ADRIAN EGGLESTONE | B6: MARCH | D6: paegg54@gmail.com | F6: EXCELLENT | G6: EXCELLENT | H6: EXCELLENT | I6: EXCELLENT | J6: EXCELLENT | K6: EXCELLENT | L6: I LIKE THE BLEND OF INFORMALITY AND PROFESSIONAL SERVICE
A7: DAVID EGGLESTONE | B7: MARCH | D7: dgegglestone@yahoo.co.uk | F7: EXCELLENT | G7: EXCELLENT | H7: EXCELLENT | I7: EXCELLENT | J7: EXCELLENT | K7: EXCELLENT | L7: A REALLY GREAT & RELAXING VISIT
A8: ROSIE EGGLESTONE | B8: MARCH | D8: changilarosie@gmail.com | F8: EXCELLENT | G8: EXCELLENT | H8: EXCELLENT | I8: EXCELLENT | J8: EXCELLENT | K8: EXCELLENT | L8: HAD AN AMAZING EXPERIENCE
A9: LYNNE EGGLESTONE | B9: MARCH | D9: lynne.egglestone@me.net | F9: EXCELLENT | G9: EXCELLENT | H9: EXCELLENT | I9: EXCELLENT | J9: EXCELLENT | K9: EXCELLENT | L9: WOULD LOVE TO COME BACK
A10: LUCY STANTON | B10: MARCH | D10: lucy@lucystanton.com.au | F10: EXCELLENT | G10: EXCELLENT | H10: EXCELLENT | I10: EXCELLENT | J10: EXCELLENT | K10: EXCELLENT | L10: THE WHOLE EXPERIENCE WAS 5-STAR.
A11: ANNA BOSMA | B11: MARCH | D11: annajongema@gmail.com | F11: EXCELLENT | G11: EXCELLENT | H11: EXCELLENT | I11: EXCELLENT | J11: EXCELLENT | K11: EXCELLENT
A12: ANN JONGEMA | B12: MARCH | D12: annajongema@gmail.com | F12: EXCELLENT | G12: EXCELLENT | H12: EXCELLENT | I12: EXCELLENT | J12: EXCELLENT | K12: EXCELLENT
A13: CRAIG FEATHERBY | B13: MARCH | F13: EXCELLENT | G13: EXCELLENT | H13: EXCELLENT | I13: EXCELLENT | J13: EXCELLENT | K13: EXCELLENT | L13: ANOTHER GREAT STAY
A14: DI FEATHERBY | B14: MARCH | D14: di@labellemaison.co.za | F14: EXCELLENT | G14: EXCELLENT | H14: EXCELLENT | I14: EXCELLENT | J14: EXCELLENT | K14: EXCELLENT | L14: ONCE AGAIN ANOTHER EUPHORIC EXPERIENCE
A15: RICHARD MEMMOTT | B15: MARCH | F15: EXCELLENT | G15: EXCELLENT | H15: EXCELLENT | I15: EXCELLENT | J15: EXCELLENT | K15: EXCELLENT
A16: NINA MEMMOTT | B16: MARCH | D16: nina.memmott@me.com | F16: EXCELLENT | G16: GOOD | H16: EXCELLENT | I16: EXCELLENT | J16: EXCELLENT | K16: EXCELLENT | L16: THE FOOD WERE REALLY GOOD.
A17: NANDY FEATHERBY | B17: MARCH | F17: EXCELLENT | G17: GOOD | H17: EXCELLENT | I17: EXCELLENT | J17: EXCELLENT | K17: EXCELLENT | L17: ANOTHER WONDERFUL EXPERIENCE.
A18: GARRY FEATHERBY | B18: MARCH | F18: EXCELLENT | G18: AVERAGE | H18: EXCELLENT | I18: EXCELLENT | J18: EXCELLENT | K18: EXCELLENT
A19: KERIE FEATHERBY | B19: MARCH | D19: kerie@flatline.co.za | F19: EXCELLENT | G19: EXCELLENT | H19: EXCELLENT | I19: EXCELLENT | J19: EXCELLENT | K19: EXCELLENT | L19: THE BEAUTIFUL SURROUNDINGS, EXCEPTIONAL SERVICE, DELICIOUS FOOD AND WONDERFUL EXPERIENCE, IT IS ALL APPRECIATED.
A20: STUART FEATHERBY | B20: MARCH | D20: stuart@flatline.co.za | F20: EXCELLENT | G20: EXCELLENT | H20: EXCELLENT | I20: EXCELLENT | J20: EXCELLENT | K20: EXCELLENT | L20: OUTSTANDING SERVICE AND MEMORABLE EXPERIENCE.
A21: CAROLINE MCARTON | B21: MARCH | D21: mcarton@live.ca | F21: EXCELLENT | G21: EXCELLENT | H21: EXCELLENT | I21: EXCELLENT | J21: EXCELLENT | K21: EXCELLENT | L21: EVERYONE WAS VERY FRIENDLY AND HELPFUL.
A22: MAX BLANKSTEIN | B22: MARCH | D22: maxblankstein@gmail.com | F22: EXCELLENT | G22: EXCELLENT | H22: EXCELLENT | I22: EXCELLENT | J22: EXCELLENT | K22: EXCELLENT | L22: NOT SURE HOW YOU CAN IMPROVE, COULD NOT FIND ANY WEAKNESS IN YOUR PRODUCT. KEEP UP THE EXCEPTIONAL WORK.
A23: ANDREW SPRAGUE | B23: MARCH | D23: asprague@amb.co.za | F23: EXCELLENT | G23: EXCELLENT | H23: EXCELLENT | I23: EXCELLENT | J23: EXCELLENT | K23: EXCELLENT | L23: EXCELLENT STAY, THANKS TO THE TEAM.
A24: MATT SPRAGUE | B24: MARCH | F24: EXCELLENT | G24: EXCELLENT | H24: EXCELLENT | I24: EXCELLENT | J24: EXCELLENT | K24: EXCELLENT | L24: THANK YOU FOR THE BEST STAY EVER. I LOVED THE FOOD, THE FISHING AND THANKS TO THE BEST WAITERS EVER.
A25: BRIGITTE DE BRUYN | B25: MARCH | D25: BRIGITTEDB@MWEB.CO.ZA | F25: EXCELLENT | G25: EXCELLENT | H25: EXCELLENT | I25: EXCELLENT | J25: EXCELLENT | K25: EXCELLENT | L25: THE FOOD WAS AMAZING AND THE STAFF WERE ATTENTIVE, FRIENDLY & VERY EFFICIENT. WHAT AN AWESOME TRIP.
A26: DICKIE KAY | B26: MARCH | D26: dmh3kay@aol.com | F26: EXCELLENT | G26: EXCELLENT | H26: EXCELLENT | I26: EXCELLENT | J26: EXCELLENT | K26: EXCELLENT | L26: ABSOLUTELY LOVELY!! WONDERFUL.
A27: HALEY SCHURZ | B27: MARCH | D27: haley@africaoutreach.net | F27: EXCELLENT | G27: EXCELLENT | H27: EXCELLENT | I27: EXCELLENT | J27: EXCELLENT | K27: EXCELLENT | L27: HAD A WONDERFUL TIME. THE STAFF WERE GREAT, AND WHEREVER I SAW THEM THEY WERE HAPPY AND HELPFUL.
A28: MARY CHANG | B28: MARCH | D28: dmh3kay@aol.com | F28: EXCELLENT | G28: EXCELLENT | H28: EXCELLENT | I28: EXCELLENT | J28: EXCELLENT | K28: EXCELLENT | L28: IT WAS LOVELY - WESTON & PETER WERE VERY PATIENT, WE FELT VERY SAFE IN THEIR HANDS.
A29: WALKER SCHURZ | B29: MARCH | D29: walker@africaoutreach.net | F29: EXCELLENT | G29: EXCELLENT | H29: EXCELLENT | I29: EXCELLENT | J29: EXCELLENT | K29: EXCELLENT | L29: 5-STAR!!!! GREAT ROOMS, FOOD (AMAZING LAMB CURRY), AND GUIDES. WILL DEFINITELY BE BACK.
A30: ALISON LOMBARD | B30: MARCH | D30: alisonlomard91@gmail.com | F30: EXCELLENT | G30: EXCELLENT | H30: EXCELLENT | I30: EXCELLENT | J30: EXCELLENT | K30: EXCELLENT | L30: THANKS FOR THE STAY!
A31: RICHARD MORROW | B31: MARCH | F31: EXCELLENT | G31: EXCELLENT | H31: GOOD | I31: EXCELLENT | J31: EXCELLENT | K31: EXCELLENT | L31: I WISH I COULD HAVE STAYED LONGER
A32: HENRY SANDS | B32: MARCH | D32: henry.sands@sabistrategy.com | F32: EXCELLENT | G32: GOOD | H32: EXCELLENT | I32: EXCELLENT | J32: EXCELLENT | K32: EXCELLENT
A33: PUNIT SHARMA | B33: MARCH | F33: EXCELLENT | G33: GOOD | H33: EXCELLENT | I33: EXCELLENT | J33: EXCELLENT | K33: EXCELLENT
A34: DAVIS MWANAMOYA | B34: MARCH | D34: davisdm@zcorsources.com | F34: EXCELLENT | G34: GOOD | H34: EXCELLENT | I34: EXCELLENT | J34: EXCELLENT | K34: EXCELLENT | L34: LOOKING FORWARD TO COMING BACK WITH MY FAMILY
A35: KLOKKE VAN BLERK | B35: MARCH | D35: francoisklokke@gmail.com | F35: EXCELLENT | G35: GOOD | H35: EXCELLENT | I35: EXCELLENT | J35: EXCELLENT | K35: EXCELLENT
A36: ZANLI VAN BLERK | B36: MARCH | D36: zjdejager@gmail.com | F36: EXCELLENT | G36: EXCELLENT | H36: EXCELLENT | I36: EXCELLENT | J36: EXCELLENT | K36: EXCELLENT | L36: WAS A REALLY WONDERFUL EXPERIENCE
A37: STUART KIRKMAN | B37: MARCH | D37: skamakzam@gmail.com | F37: EXCELLENT | G37: EXCELLENT | H37: EXCELLENT | I37: EXCELLENT | J37: EXCELLENT | K37: EXCELLENT | L37: WHAT AN AMAZING 3-DAYS WE HAD.A BEAUTIFUL AND A TOP RATE STAFF COMPLIMENT.
A38: KERRY KIRKMAN | B38: MARCH | D38: skamakzam@gmail.com | F38: EXCELLENT | G38: EXCELLENT | H38: EXCELLENT | I38: EXCELLENT | J38: EXCELLENT | K38: EXCELLENT | L38: WHAT AN AMAZING MEMORY WE HAVE MADE. WE WILL BE BACK.
A39: RYAN STICKEL | B39: MARCH | D39: stickelryan@gmail.com | F39: EXCELLENT | G39: EXCELLENT | H39: EXCELLENT | I39: EXCELLENT | J39: EXCELLENT | K39: EXCELLENT
A40: MAUREEN STICKEL | B40: MARCH | D40: mostickel@gmail.com | F40: EXCELLENT | G40: EXCELLENT | H40: EXCELLENT | I40: EXCELLENT | J40: EXCELLENT | K40: EXCELLENT | L40: THANK YOU FOR SUCH A NICE STAY. YOUR TEAM WENT ABOVE & BEYOND FOR US AND OUR KIDS. WE WILL BE BACK.
A41: KERRY KIRBY | B41: MARCH | D41: kerrykirbs@gmail.com | F41: EXCELLENT | G41: GOOD | H41: GOOD | I41: EXCELLENT | J41: GOOD | K41: EXCELLENT | L41: BEST STEAKS EVER.
...

Sheet Summary
B1: Service | C1: Food | D1: Activities | E1: Lodge Staff | F1: Accomodation | G1: Overall Stay
A3: Poor | B3: =COUNTIF(Data!F3:F3289,$A$3) -> 0 | C3: =COUNTIF(Data!G3:G3289,$A$3) -> 0 | D3: =COUNTIF(Data!H3:H3289,$A$3) -> 0 | E3: =COUNTIF(Data!I3:I3289,$A$3) -> 0 | F3: =COUNTIF(Data!J3:J3289,$A$3) -> 0 | G3: =COUNTIF(Data!K3:K3289,$A$3) -> 0
A4: Average | B4: =COUNTIF(Data!F3:F3289,$A$4) -> 0 | C4: =COUNTIF(Data!G3:G3289,$A$4) -> 2 | D4: =COUNTIF(Data!H3:H3289,$A$4) -> 1 | E4: =COUNTIF(Data!I3:I3289,$A$4) -> 0 | F4: =COUNTIF(Data!J3:J3289,$A$4) -> 0 | G4: =COUNTIF(Data!K3:K3289,$A$4) -> 0
A5: Good | B5: =COUNTIF(Data!F3:F3289,$A$5) -> 6 | C5: =COUNTIF(Data!G3:G3289,$A$5) -> 48 | D5: =COUNTIF(Data!H3:H3289,$A$5) -> 24 | E5: =COUNTIF(Data!I3:I3289,$A$5) -> 4 | F5: =COUNTIF(Data!J3:J3289,$A$5) -> 20 | G5: =COUNTIF(Data!K3:K3289,$A$5) -> 13
A6: Excellent | B6: =COUNTIF(Data!F3:F3289,$A$6) -> 326 | C6: =COUNTIF(Data!G3:G3289,$A$6) -> 281 | D6: =COUNTIF(Data!H3:H3289,$A$6) -> 306 | E6: =COUNTIF(Data!I3:I3289,$A$6) -> 328 | F6: =COUNTIF(Data!J3:J3289,$A$6) -> 312 | G6: =COUNTIF(Data!K3:K3289,$A$6) -> 319
A8: Total | B8: =SUM(B2:B7) -> 332 | C8: =SUM(C2:C7) -> 331 | D8: =SUM(D2:D7) -> 331 | E8: =SUM(E2:E7) -> 332 | F8: =SUM(F2:F7) -> 332 | G8: =SUM(G2:G7) -> 332
B11: Service | C11: Food | D11: Activities | E11: Lodge Staff | F11: Accomodation | G11: Overall Stay
A13: Poor | B13: =B3/$B$8 -> 0 | C13: =C3/$C$8 -> 0 | D13: =D3/$D$8 -> 0 | E13: =E3/$E$8 -> 0 | F13: =F3/$F$8 -> 0 | G13: =G3/$G$8 -> 0
A14: Average | B14: =B4/$B$8 -> 0 | C14: =C4/$C$8 -> 0.0060422961 | D14: =D4/$D$8 -> 0.003021148 | E14: =E4/$E$8 -> 0 | F14: =F4/$F$8 -> 0 | G14: =G4/$G$8 -> 0
A15: Good | B15: =B5/$B$8 -> 0.018072289 | C15: =C5/$C$8 -> 0.14501511 | D15: =D5/$D$8 -> 0.072507553 | E15: =E5/$E$8 -> 0.012048193 | F15: =F5/$F$8 -> 0.060240964 | G15: =G5/$G$8 -> 0.039156627
A16: Excellent | B16: =B6/$B$8 -> 0.98192771 | C16: =C6/$C$8 -> 0.8489426 | D16: =D6/$D$8 -> 0.9244713 | E16: =E6/$E$8 -> 0.98795181 | F16: =F6/$F$8 -> 0.93975904 | G16: =G6/$G$8 -> 0.96084337

Sheet Sheet1
A1: Month | B1: Rating | C1: Service | D1: Food | E1: Activities | F1: Lodge Staff | G1: Accomodation | H1: Overall Stay
A2: Janaury | B2: Poor
B3: Average
B4: Good
B5: Excellent
A6: February | B6: Poor
B7: Average
B8: Good
B9: Excellent
A10: March | B10: Poor
B11: Average
B12: Good
B13: Excellent
A14: April | B14: Poor
B15: Average
B16: Good
B17: Excellent
A18: May | B18: Poor | C18: =COUNTIF(Data!$F$4:$F$4,Sheet1!$B$18) -> 0 | D18: =COUNTIF(Data!$G$4:$G$4,Sheet1!$B$18) -> 0 | E18: =COUNTIF(Data!$H$4:$H$4,Sheet1!$B$18) -> 0 | F18: =COUNTIF(Data!$I$4:$I$4,Sheet1!$B$18) -> 0 | G18: =COUNTIF(Data!$J$4:$J$4,Sheet1!$B$18) -> 0 | H18: =COUNTIF(Data!$K$4:$K$4,Sheet1!$B$18) -> 0
B19: Average | C19: =COUNTIF(Data!$F$4:$F$4,Sheet1!$B$19) -> 0 | D19: =COUNTIF(Data!$G$4:$G$4,Sheet1!$B$19) -> 0 | E19: =COUNTIF(Data!$H$4:$H$4,Sheet1!$B$19) -> 0 | F19: =COUNTIF(Data!$I$4:$I$4,Sheet1!$B$19) -> 0 | G19: =COUNTIF(Data!$J$4:$J$4,Sheet1!$B$19) -> 0 | H19: =COUNTIF(Data!$K$4:$K$4,Sheet1!$B$19) -> 0
B20: Good | C20: =COUNTIF(Data!$F$4:$F$4,Sheet1!$B$20) -> 0 | D20: =COUNTIF(Data!$G$4:$G$4,Sheet1!$B$20) -> 0 | E20: =COUNTIF(Data!$H$4:$H$4,Sheet1!$B$20) -> 0 | F20: =COUNTIF(Data!$I$4:$I$4,Sheet1!$B$20) -> 0 | G20: =COUNTIF(Data!$J$4:$J$4,Sheet1!$B$20) -> 0 | H20: =COUNTIF(Data!$K$4:$K$4,Sheet1!$B$20) -> 0
B21: Excellent | C21: =COUNTIF(Data!$F$4:$F$4,Sheet1!$B$21) -> 1 | D21: =COUNTIF(Data!$G$4:$G$4,Sheet1!$B$21) -> 1 | E21: =COUNTIF(Data!$H$4:$H$4,Sheet1!$B$21) -> 1 | F21: =COUNTIF(Data!$I$4:$I$4,Sheet1!$B$21) -> 1 | G21: =COUNTIF(Data!$J$4:$J$4,Sheet1!$B$21) -> 1 | H21: =COUNTIF(Data!$K$4:$K$4,Sheet1!$B$21) -> 1
A22: June | B22: Poor | C22: =COUNTIF(Data!$F$5:$F$51,Sheet1!$B$22) -> 0 | D22: =COUNTIF(Data!$G$5:$G$51,Sheet1!$B$22) -> 0 | E22: =COUNTIF(Data!$H$5:$H$51,Sheet1!$B$22) -> 0 | F22: =COUNTIF(Data!$I$5:$I$51,Sheet1!$B$22) -> 0 | G22: =COUNTIF(Data!$J$5:$J$51,Sheet1!$B$22) -> 0 | H22: =COUNTIF(Data!$K$5:$K$51,Sheet1!$B$22) -> 0
B23: Average | C23: =COUNTIF(Data!$F$5:$F$51,Sheet1!$B$23) -> 0 | D23: =COUNTIF(Data!$G$5:$G$51,Sheet1!$B$23) -> 1 | E23: =COUNTIF(Data!$H$5:$H$51,Sheet1!$B$23) -> 0 | F23: =COUNTIF(Data!$I$5:$I$51,Sheet1!$B$23) -> 0 | G23: =COUNTIF(Data!$J$5:$J$51,Sheet1!$B$23) -> 0 | H23: =COUNTIF(Data!$K$5:$K$51,Sheet1!$B$23) -> 0
B24: Good | C24: =COUNTIF(Data!$F$5:$F$51,Sheet1!$B$24) -> 0 | D24: =COUNTIF(Data!$G$5:$G$51,Sheet1!$B$24) -> 8 | E24: =COUNTIF(Data!$H$5:$H$51,Sheet1!$B$24) -> 2 | F24: =COUNTIF(Data!$I$5:$I$51,Sheet1!$B$24) -> 0 | G24: =COUNTIF(Data!$J$5:$J$51,Sheet1!$B$24) -> 1 | H24: =COUNTIF(Data!$K$5:$K$51,Sheet1!$B$24) -> 0
B25: Excellent | C25: =COUNTIF(Data!$F$5:$F$51,Sheet1!$B$25) -> 47 | D25: =COUNTIF(Data!$G$5:$G$51,Sheet1!$B$25) -> 38 | E25: =COUNTIF(Data!$H$5:$H$51,Sheet1!$B$25) -> 45 | F25: =COUNTIF(Data!$I$5:$I$51,Sheet1!$B$25) -> 47 | G25: =COUNTIF(Data!$J$5:$J$51,Sheet1!$B$25) -> 46 | H25: =COUNTIF(Data!$K$5:$K$51,Sheet1!$B$25) -> 47
A26: July | B26: Poor | C26: =COUNTIF(Data!$F$52:$F$108,Sheet1!$B$26) -> 0 | D26: =COUNTIF(Data!$G$52:$G$108,Sheet1!$B$26) -> 0 | E26: =COUNTIF(Data!$H$52:$H$108,Sheet1!$B$26) -> 0 | F26: =COUNTIF(Data!$I$52:$I$108,Sheet1!$B$26) -> 0 | G26: =COUNTIF(Data!$J$52:$J$108,Sheet1!$B$26) -> 0 | H26: =COUNTIF(Data!$K$52:$K$108,Sheet1!$B$26) -> 0
B27: Average | C27: =COUNTIF(Data!$F$52:$F$108,Sheet1!$B$27) -> 0 | D27: =COUNTIF(Data!$G$52:$G$108,Sheet1!$B$27) -> 0 | E27: =COUNTIF(Data!$H$52:$H$108,Sheet1!$B$27) -> 0 | F27: =COUNTIF(Data!$I$52:$I$108,Sheet1!$B$27) -> 0 | G27: =COUNTIF(Data!$J$52:$J$108,Sheet1!$B$27) -> 0 | H27: =COUNTIF(Data!$K$52:$K$108,Sheet1!$B$27) -> 0
B28: Good | C28: =COUNTIF(Data!$F$52:$F$108,Sheet1!$B$28) -> 0 | D28: =COUNTIF(Data!$G$52:$G$108,Sheet1!$B$28) -> 6 | E28: =COUNTIF(Data!$H$52:$H$108,Sheet1!$B$28) -> 1 | F28: =COUNTIF(Data!$I$52:$I$108,Sheet1!$B$28) -> 0 | G28: =COUNTIF(Data!$J$52:$J$108,Sheet1!$B$28) -> 3 | H28: =COUNTIF(Data!$K$52:$K$108,Sheet1!$B$28) -> 1
B29: Excellent | C29: =COUNTIF(Data!$F$52:$F$108,Sheet1!$B$29) -> 57 | D29: =COUNTIF(Data!$G$52:$G$108,Sheet1!$B$29) -> 51 | E29: =COUNTIF(Data!$H$52:$H$108,Sheet1!$B$29) -> 56 | F29: =COUNTIF(Data!$I$52:$I$108,Sheet1!$B$29) -> 57 | G29: =COUNTIF(Data!$J$52:$J$108,Sheet1!$B$29) -> 54 | H29: =COUNTIF(Data!$K$52:$K$108,Sheet1!$B$29) -> 56
A30: August | B30: Poor | C30: =COUNTIF(Data!#REF!,Sheet1!$B$30) -> #REF! | D30: =COUNTIF(Data!#REF!,Sheet1!$B$30) -> #REF! | E30: =COUNTIF(Data!#REF!,Sheet1!$B$30) -> #REF! | F30: =COUNTIF(Data!#REF!,Sheet1!$B$30) -> #REF! | G30: =COUNTIF(Data!#REF!,Sheet1!$B$30) -> #REF! | H30: =COUNTIF(Data!#REF!,Sheet1!$B$30) -> #REF!
B31: Average | C31: =COUNTIF(Data!#REF!,Sheet1!$B$31) -> #REF! | D31: =COUNTIF(Data!#REF!,Sheet1!$B$31) -> #REF! | E31: =COUNTIF(Data!#REF!,Sheet1!$B$31) -> #REF! | F31: =COUNTIF(Data!#REF!,Sheet1!$B$31) -> #REF! | G31: =COUNTIF(Data!#REF!,Sheet1!$B$31) -> #REF! | H31: =COUNTIF(Data!#REF!,Sheet1!$B$31) -> #REF!
B32: Good | C32: =COUNTIF(Data!#REF!,Sheet1!$B$32) -> #REF! | D32: =COUNTIF(Data!#REF!,Sheet1!$B$32) -> #REF! | E32: =COUNTIF(Data!#REF!,Sheet1!$B$32) -> #REF! | F32: =COUNTIF(Data!#REF!,Sheet1!$B$32) -> #REF! | G32: =COUNTIF(Data!#REF!,Sheet1!$B$32) -> #REF! | H32: =COUNTIF(Data!#REF!,Sheet1!$B$32) -> #REF!
B33: Excellent | C33: =COUNTIF(Data!#REF!,Sheet1!$B$33) -> #REF! | D33: =COUNTIF(Data!#REF!,Sheet1!$B$33) -> #REF! | E33: =COUNTIF(Data!#REF!,Sheet1!$B$33) -> #REF! | F33: =COUNTIF(Data!#REF!,Sheet1!$B$33) -> #REF! | G33: =COUNTIF(Data!#REF!,Sheet1!$B$33) -> #REF! | H33: =COUNTIF(Data!#REF!,Sheet1!$B$33) -> #REF!
A34: September | B34: Poor | C34: =COUNTIF(Data!#REF!,Sheet1!$B$34) -> #REF! | D34: =COUNTIF(Data!#REF!,Sheet1!$B$34) -> #REF! | E34: =COUNTIF(Data!#REF!,Sheet1!$B$34) -> #REF! | F34: =COUNTIF(Data!#REF!,Sheet1!$B$34) -> #REF! | G34: =COUNTIF(Data!#REF!,Sheet1!$B$34) -> #REF! | H34: =COUNTIF(Data!#REF!,Sheet1!$B$34) -> #REF!
B35: Average | C35: =COUNTIF(Data!#REF!,Sheet1!$B$35) -> #REF! | D35: =COUNTIF(Data!#REF!,Sheet1!$B$35) -> #REF! | E35: =COUNTIF(Data!#REF!,Sheet1!$B$35) -> #REF! | F35: =COUNTIF(Data!#REF!,Sheet1!$B$35) -> #REF! | G35: =COUNTIF(Data!#REF!,Sheet1!$B$35) -> #REF! | H35: =COUNTIF(Data!#REF!,Sheet1!$B$35) -> #REF!
B36: Good | C36: =COUNTIF(Data!#REF!,Sheet1!$B$36) -> #REF! | D36: =COUNTIF(Data!#REF!,Sheet1!$B$36) -> #REF! | E36: =COUNTIF(Data!#REF!,Sheet1!$B$36) -> #REF! | F36: =COUNTIF(Data!#REF!,Sheet1!$B$36) -> #REF! | G36: =COUNTIF(Data!#REF!,Sheet1!$B$36) -> #REF! | H36: =COUNTIF(Data!#REF!,Sheet1!$B$36) -> #REF!
B37: Excellent | C37: =COUNTIF(Data!#REF!,Sheet1!$B$37) -> #REF! | D37: =COUNTIF(Data!#REF!,Sheet1!$B$37) -> #REF! | E37: =COUNTIF(Data!#REF!,Sheet1!$B$37) -> #REF! | F37: =COUNTIF(Data!#REF!,Sheet1!$B$37) -> #REF! | G37: =COUNTIF(Data!#REF!,Sheet1!$B$37) -> #REF! | H37: =COUNTIF(Data!#REF!,Sheet1!$B$37) -> #REF!
A38: October | B38: Poor | C38: =COUNTIF(Data!#REF!,Sheet1!$B$38) -> #REF! | D38: =COUNTIF(Data!#REF!,Sheet1!$B$38) -> #REF! | E38: =COUNTIF(Data!#REF!,Sheet1!$B$38) -> #REF! | F38: =COUNTIF(Data!#REF!,Sheet1!$B$38) -> #REF! | G38: =COUNTIF(Data!#REF!,Sheet1!$B$38) -> #REF! | H38: =COUNTIF(Data!#REF!,Sheet1!$B$38) -> #REF!
B39: Average | C39: =COUNTIF(Data!#REF!,Sheet1!$B$39) -> #REF! | D39: =COUNTIF(Data!#REF!,Sheet1!$B$39) -> #REF! | E39: =COUNTIF(Data!#REF!,Sheet1!$B$39) -> #REF! | F39: =COUNTIF(Data!#REF!,Sheet1!$B$39) -> #REF! | G39: =COUNTIF(Data!#REF!,Sheet1!$B$39) -> #REF! | H39: =COUNTIF(Data!#REF!,Sheet1!$B$39) -> #REF!
B40: Good | C40: =COUNTIF(Data!#REF!,Sheet1!$B$40) -> #REF! | D40: =COUNTIF(Data!#REF!,Sheet1!$B$40) -> #REF! | E40: =COUNTIF(Data!#REF!,Sheet1!$B$40) -> #REF! | F40: =COUNTIF(Data!#REF!,Sheet1!$B$40) -> #REF! | G40: =COUNTIF(Data!#REF!,Sheet1!$B$40) -> #REF! | H40: =COUNTIF(Data!#REF!,Sheet1!$B$40) -> #REF!
...

Sheet Sheet1 (2)
A1: Month | B1: Service | H1: Food | N1: Activities | T1: Lodge Staff | Z1: Accomodation | AG1: Overall Stay | AL1: Comment Cards in the month
B2: Poor | C2: Average | D2: Good | E2: Excellent | H2: Poor | I2: Average | J2: Good | K2: Excellent | N2: Poor | O2: Average | P2: Good | Q2: Excellent | T2: Poor | U2: Average | V2: Good | W2: Excellent | Z2: Poor | AA2: Average | AB2: Good | AC2: Excellent | AG2: Poor | AH2: Average | AI2: Good | AJ2: Excellent
A4: Janaury | G4: Janaury | M4: Janaury | S4: Janaury | Y4: Janaury | AF4: Janaury
A5: February | G5: February | M5: February | S5: February | Y5: February | AF5: February
A6: March | G6: March | M6: March | S6: March | Y6: March | AF6: March
A7: April | G7: April | M7: April | S7: April | Y7: April | AF7: April
A8: May | B8: =COUNTIF(Data!$F$4:$F$4,$B$2) -> 0 | C8: =COUNTIF(Data!$F$4:$F$4,$C$2) -> 0 | D8: =COUNTIF(Data!$F$4:$F$4,$D$2) -> 0 | E8: =COUNTIF(Data!$F$4:$F$4,$E$2) -> 1 | F8: =SUM(B8:E8) -> 1 | G8: May | H8: =COUNTIF(Data!$G$4:$G$4,$H$2) -> 0 | I8: =COUNTIF(Data!$G$4:$G$4,$I$2) -> 0 | J8: =COUNTIF(Data!$G$4:$G$4,$J$2) -> 0 | K8: =COUNTIF(Data!$G$4:$G$4,$K$2) -> 1 | L8: =SUM(H8:K8) -> 1 | M8: May | N8: =COUNTIF(Data!$H$4:$H$4,$N$2) -> 0 | O8: =COUNTIF(Data!$H$4:$H$4,$O$2) -> 0 | P8: =COUNTIF(Data!$H$4:$H$4,$P$2) -> 0 | Q8: =COUNTIF(Data!$H$4:$H$4,$Q$2) -> 1 | R8: =SUM(N8:Q8) -> 1 | S8: May | T8: =COUNTIF(Data!$I$4:$I$4,$T$2) -> 0 | U8: =COUNTIF(Data!$I$4:$I$4,$U$2) -> 0 | V8: =COUNTIF(Data!$I$4:$I$4,$V$2) -> 0 | W8: =COUNTIF(Data!$I$4:$I$4,$W$2) -> 1 | X8: =SUM(T8:W8) -> 1 | Y8: May | Z8: =COUNTIF(Data!$J$4:$J$4,$Z$2) -> 0 | AA8: =COUNTIF(Data!$J$4:$J$4,$AA$2) -> 0 | AB8: =COUNTIF(Data!$J$4:$J$4,$AB$2) -> 0 | AC8: =COUNTIF(Data!$J$4:$J$4,$AC$2) -> 1 | AD8: =SUM(Z8:AC8) -> 1 | AF8: May | AG8: =COUNTIF(Data!$K$4:$K$4,$AG$2) -> 0 | AH8: =COUNTIF(Data!$K$4:$K$4,$AH$2) -> 0 | AI8: =COUNTIF(Data!$K$4:$K$4,$AI$2) -> 0 | AJ8: =COUNTIF(Data!$K$4:$K$4,$AJ$2) -> 1 | AK8: =SUM(AG8:AJ8) -> 1 | AL8: =COUNTA(Data!A4) -> 1
A9: June | B9: =COUNTIF(Data!$F$5:$F$51,$B$2) -> 0 | C9: =COUNTIF(Data!$F$5:$F$51,$C$2) -> 0 | D9: =COUNTIF(Data!$F$5:$F$51,$D$2) -> 0 | E9: =COUNTIF(Data!$F$5:$F$51,$E$2) -> 47 | F9: =SUM(B9:E9) -> 47 | G9: June | H9: =COUNTIF(Data!$G$5:$G$51,$H$2) -> 0 | I9: =COUNTIF(Data!$G$5:$G$51,$I$2) -> 1 | J9: =COUNTIF(Data!$G$5:$G$51,$J$2) -> 8 | K9: =COUNTIF(Data!$G$5:$G$51,$K$2) -> 38 | L9: =SUM(H9:K9) -> 47 | M9: June | N9: =COUNTIF(Data!$H$5:$H$51,$N$2) -> 0 | O9: =COUNTIF(Data!$H$5:$H$51,$O$2) -> 0 | P9: =COUNTIF(Data!$H$5:$H$51,$P$2) -> 2 | Q9: =COUNTIF(Data!$H$5:$H$51,$Q$2) -> 45 | R9: =SUM(N9:Q9) -> 47 | S9: June | T9: =COUNTIF(Data!$I$5:$I$51,$T$2) -> 0 | U9: =COUNTIF(Data!$I$5:$I$51,$U$2) -> 0 | V9: =COUNTIF(Data!$I$5:$I$51,$V$2) -> 0 | W9: =COUNTIF(Data!$I$5:$I$51,$W$2) -> 47 | X9: =SUM(T9:W9) -> 47 | Y9: June | Z9: =COUNTIF(Data!$J$5:$J$51,$Z$2) -> 0 | AA9: =COUNTIF(Data!$J$5:$J$51,$AA$2) -> 0 | AB9: =COUNTIF(Data!$J$5:$J$51,$AB$2) -> 1 | AC9: =COUNTIF(Data!$J$5:$J$51,$AC$2) -> 46 | AD9: =SUM(Z9:AC9) -> 47 | AF9: June | AG9: =COUNTIF(Data!$K$5:$K$51,$AG$2) -> 0 | AH9: =COUNTIF(Data!$K$5:$K$51,$AH$2) -> 0 | AI9: =COUNTIF(Data!$K$5:$K$51,$AI$2) -> 0 | AJ9: =COUNTIF(Data!$K$5:$K$51,$AJ$2) -> 47 | AK9: =SUM(AG9:AJ9) -> 47 | AL9: =COUNTA(Data!A5:A51) -> 47
A10: July | B10: =COUNTIF(Data!$F$52:$F$108,$B$2) -> 0 | C10: =COUNTIF(Data!$F$52:$F$108,$C$2) -> 0 | D10: =COUNTIF(Data!$F$52:$F$108,$D$2) -> 0 | E10: =COUNTIF(Data!$F$52:$F$108,$E$2) -> 57 | F10: =SUM(B10:E10) -> 57 | G10: July | H10: =COUNTIF(Data!$G$52:$G$108,$H$2) -> 0 | I10: =COUNTIF(Data!$G$52:$G$108,$I$2) -> 0 | J10: =COUNTIF(Data!$G$52:$G$108,$J$2) -> 6 | K10: =COUNTIF(Data!$G$52:$G$108,$K$2) -> 51 | L10: =SUM(H10:K10) -> 57 | M10: July | N10: =COUNTIF(Data!$H$52:$H$108,$N$2) -> 0 | O10: =COUNTIF(Data!$H$52:$H$108,$O$2) -> 0 | P10: =COUNTIF(Data!$H$52:$H$108,$P$2) -> 1 | Q10: =COUNTIF(Data!$H$52:$H$108,$Q$2) -> 56 | R10: =SUM(N10:Q10) -> 57 | S10: July | T10: =COUNTIF(Data!$I$52:$I$108,$T$2) -> 0 | U10: =COUNTIF(Data!$I$52:$I$108,$U$2) -> 0 | V10: =COUNTIF(Data!$I$52:$I$108,$V$2) -> 0 | W10: =COUNTIF(Data!$I$52:$I$108,$W$2) -> 57 | X10: =SUM(T10:W10) -> 57 | Y10: July | Z10: =COUNTIF(Data!$J$52:$J$108,$Z$2) -> 0 | AA10: =COUNTIF(Data!$J$52:$J$108,$AA$2) -> 0 | AB10: =COUNTIF(Data!$J$52:$J$108,$AB$2) -> 3 | AC10: =COUNTIF(Data!$J$52:$J$108,$AC$2) -> 54 | AD10: =SUM(Z10:AC10) -> 57 | AF10: July | AG10: =COUNTIF(Data!$K$52:$K$108,$AG$2) -> 0 | AH10: =COUNTIF(Data!$K$52:$K$108,$AH$2) -> 0 | AI10: =COUNTIF(Data!$K$52:$K$108,$AI$2) -> 1 | AJ10: =COUNTIF(Data!$K$52:$K$108,$AJ$2) -> 56 | AK10: =SUM(AG10:AJ10) -> 57 | AL10: =COUNTA(Data!A52:A108) -> 56
A11: August | B11: =COUNTIF(Data!#REF!,$B$2) -> #REF! | C11: =COUNTIF(Data!#REF!,$C$2) -> #REF! | D11: =COUNTIF(Data!#REF!,$D$2) -> #REF! | E11: =COUNTIF(Data!#REF!,$E$2) -> #REF! | F11: =SUM(B11:E11) -> #REF! | G11: August | H11: =COUNTIF(Data!#REF!,$H$2) -> #REF! | I11: =COUNTIF(Data!#REF!,$I$2) -> #REF! | J11: =COUNTIF(Data!#REF!,$J$2) -> #REF! | K11: =COUNTIF(Data!#REF!,$K$2) -> #REF! | L11: =SUM(H11:K11) -> #REF! | M11: August | N11: =COUNTIF(Data!#REF!,$N$2) -> #REF! | O11: =COUNTIF(Data!#REF!,$O$2) -> #REF! | P11: =COUNTIF(Data!#REF!,$P$2) -> #REF! | Q11: =COUNTIF(Data!#REF!,$Q$2) -> #REF! | R11: =SUM(N11:Q11) -> #REF! | S11: August | T11: =COUNTIF(Data!#REF!,$T$2) -> #REF! | U11: =COUNTIF(Data!#REF!,$U$2) -> #REF! | V11: =COUNTIF(Data!#REF!,$V$2) -> #REF! | W11: =COUNTIF(Data!#REF!,$W$2) -> #REF! | X11: =SUM(T11:W11) -> #REF! | Y11: August | Z11: =COUNTIF(Data!#REF!,$Z$2) -> #REF! | AA11: =COUNTIF(Data!#REF!,$AA$2) -> #REF! | AB11: =COUNTIF(Data!#REF!,$AB$2) -> #REF! | AC11: =COUNTIF(Data!#REF!,$AC$2) -> #REF! | AD11: =SUM(Z11:AC11) -> #REF! | AF11: August | AG11: =COUNTIF(Data!#REF!,$AG$2) -> #REF! | AH11: =COUNTIF(Data!#REF!,$AH$2) -> #REF! | AI11: =COUNTIF(Data!#REF!,$AI$2) -> #REF! | AJ11: =COUNTIF(Data!#REF!,$AJ$2) -> #REF! | AK11: =SUM(AG11:AJ11) -> #REF! | AL11: =COUNTA(Data!#REF!) -> 1
A12: September | B12: =COUNTIF(Data!#REF!,$B$2) -> #REF! | C12: =COUNTIF(Data!#REF!,$C$2) -> #REF! | D12: =COUNTIF(Data!#REF!,$D$2) -> #REF! | E12: =COUNTIF(Data!#REF!,$E$2) -> #REF! | F12: =SUM(B12:E12) -> #REF! | G12: September | H12: =COUNTIF(Data!#REF!,$H$2) -> #REF! | I12: =COUNTIF(Data!#REF!,$I$2) -> #REF! | J12: =COUNTIF(Data!#REF!,$J$2) -> #REF! | K12: =COUNTIF(Data!#REF!,$K$2) -> #REF! | L12: =SUM(H12:K12) -> #REF! | M12: September | N12: =COUNTIF(Data!#REF!,$N$2) -> #REF! | O12: =COUNTIF(Data!#REF!,$O$2) -> #REF! | P12: =COUNTIF(Data!#REF!,$P$2) -> #REF! | Q12: =COUNTIF(Data!#REF!,$Q$2) -> #REF! | R12: =SUM(N12:Q12) -> #REF! | S12: September | T12: =COUNTIF(Data!#REF!,$T$2) -> #REF! | U12: =COUNTIF(Data!#REF!,$U$2) -> #REF! | V12: =COUNTIF(Data!#REF!,$V$2) -> #REF! | W12: =COUNTIF(Data!#REF!,$W$2) -> #REF! | X12: =SUM(T12:W12) -> #REF! | Y12: September | Z12: =COUNTIF(Data!#REF!,$Z$2) -> #REF! | AA12: =COUNTIF(Data!#REF!,$AA$2) -> #REF! | AB12: =COUNTIF(Data!#REF!,$AB$2) -> #REF! | AC12: =COUNTIF(Data!#REF!,$AC$2) -> #REF! | AD12: =SUM(Z12:AC12) -> #REF! | AF12: September | AG12: =COUNTIF(Data!#REF!,$AG$2) -> #REF! | AH12: =COUNTIF(Data!#REF!,$AH$2) -> #REF! | AI12: =COUNTIF(Data!#REF!,$AI$2) -> #REF! | AJ12: =COUNTIF(Data!#REF!,$AJ$2) -> #REF! | AK12: =SUM(AG12:AJ12) -> #REF! | AL12: =COUNTA(Data!#REF!) -> 1
A13: October | B13: =COUNTIF(Data!#REF!,$B$2) -> #REF! | C13: =COUNTIF(Data!#REF!,$C$2) -> #REF! | D13: =COUNTIF(Data!#REF!,$D$2) -> #REF! | E13: =COUNTIF(Data!#REF!,$E$2) -> #REF! | F13: =SUM(B13:E13) -> #REF! | G13: October | H13: =COUNTIF(Data!#REF!,$H$2) -> #REF! | I13: =COUNTIF(Data!#REF!,$I$2) -> #REF! | J13: =COUNTIF(Data!#REF!,$J$2) -> #REF! | K13: =COUNTIF(Data!#REF!,$K$2) -> #REF! | L13: =SUM(H13:K13) -> #REF! | M13: October | N13: =COUNTIF(Data!#REF!,$N$2) -> #REF! | O13: =COUNTIF(Data!#REF!,$O$2) -> #REF! | P13: =COUNTIF(Data!#REF!,$P$2) -> #REF! | Q13: =COUNTIF(Data!#REF!,$Q$2) -> #REF! | R13: =SUM(N13:Q13) -> #REF! | S13: October | T13: =COUNTIF(Data!#REF!,$T$2) -> #REF! | U13: =COUNTIF(Data!#REF!,$U$2) -> #REF! | V13: =COUNTIF(Data!#REF!,$V$2) -> #REF! | W13: =COUNTIF(Data!#REF!,$W$2) -> #REF! | X13: =SUM(T13:W13) -> #REF! | Y13: October | Z13: =COUNTIF(Data!#REF!,$Z$2) -> #REF! | AA13: =COUNTIF(Data!#REF!,$AA$2) -> #REF! | AB13: =COUNTIF(Data!#REF!,$AB$2) -> #REF! | AC13: =COUNTIF(Data!#REF!,$AC$2) -> #REF! | AD13: =SUM(Z13:AC13) -> #REF! | AF13: October | AG13: =COUNTIF(Data!#REF!,$AG$2) -> #REF! | AH13: =COUNTIF(Data!#REF!,$AH$2) -> #REF! | AI13: =COUNTIF(Data!#REF!,$AI$2) -> #REF! | AJ13: =COUNTIF(Data!#REF!,$AJ$2) -> #REF! | AK13: =SUM(AG13:AJ13) -> #REF! | AL13: =COUNTA(Data!#REF!) -> 1
A14: November | G14: November | M14: November | S14: November | Y14: November | AF14: November
A15: December | G15: December | M15: December | S15: December | Y15: December | AF15: December | AL15: =SUM(AL7:AL14) -> 107
A18: Janaury
A19: February
A20: March
A21: April
A22: May | B22: =B8/C8 -> #DIV/0! | C22: =C8/D8 -> #DIV/0! | D22: =D8/E8 -> 0 | E22: =E8/F8 -> 1 | H22: =H8/I8 -> #DIV/0! | I22: =I8/J8 -> #DIV/0! | J22: =J8/K8 -> 0 | K22: =K8/L8 -> 1 | N22: =N8/$AL$8 -> 0 | O22: =O8/$AL$8 -> 0 | P22: =P8/$AL$8 -> 0 | Q22: =Q8/$AL$8 -> 1 | R22: =AVERAGE(N22:Q22) -> 0.25 | T22: =T8/$AL$8 -> 0 | U22: =U8/$AL$8 -> 0 | V22: =V8/$AL$8 -> 0 | W22: =W8/$AL$8 -> 1 | X22: =AVERAGE(T22:W22) -> 0.25 | Z22: =Z8/$AL$8 -> 0 | AA22: =AA8/$AL$8 -> 0 | AB22: =AB8/$AL$8 -> 0 | AC22: =AC8/$AL$8 -> 1 | AD22: =AVERAGE(Z22:AC22) -> 0.25 | AG22: =AG8/$AL$8 -> 0 | AH22: =AH8/$AL$8 -> 0 | AI22: =AI8/$AL$8 -> 0 | AJ22: =AJ8/$AL$8 -> 1 | AK22: =AVERAGE(AG22:AJ22) -> 0.25
A23: June | B23: =B9/C9 -> #DIV/0! | C23: =C9/D9 -> #DIV/0! | D23: =D9/E9 -> 0 | E23: =E9/F9 -> 1 | H23: =H9/I9 -> 0 | I23: =I9/J9 -> 0.125 | J23: =J9/K9 -> 0.21052632 | K23: =K9/L9 -> 0.80851064 | N23: =N9/$AL$9 -> 0 | O23: =O9/$AL$9 -> 0 | P23: =P9/$AL$9 -> 0.042553191 | Q23: =Q9/$AL$9 -> 0.95744681 | R23: =AVERAGE(N23:Q23) -> 0.25 | T23: =T9/$AL$9 -> 0 | U23: =U9/$AL$9 -> 0 | V23: =V9/$AL$9 -> 0 | W23: =W9/$AL$9 -> 1 | X23: =AVERAGE(T23:W23) -> 0.25 | Z23: =Z9/$AL$9 -> 0 | AA23: =AA9/$AL$9 -> 0 | AB23: =AB9/$AL$9 -> 0.021276596 | AC23: =AC9/$AL$9 -> 0.9787234 | AD23: =AVERAGE(Z23:AC23) -> 0.25 | AG23: =AG9/$AL$9 -> 0 | AH23: =AH9/$AL$9 -> 0 | AI23: =AI9/$AL$9 -> 0 | AJ23: =AJ9/$AL$9 -> 1 | AK23: =AVERAGE(AG23:AJ23) -> 0.25
A24: July | B24: =B10/C10 -> #DIV/0! | C24: =C10/D10 -> #DIV/0! | D24: =D10/E10 -> 0 | E24: =E10/F10 -> 1 | H24: =H10/I10 -> #DIV/0! | I24: =I10/J10 -> 0 | J24: =J10/K10 -> 0.11764706 | K24: =K10/L10 -> 0.89473684 | N24: =N10/$AL$10 -> 0 | O24: =O10/$AL$10 -> 0 | P24: =P10/$AL$10 -> 0.017857143 | Q24: =Q10/$AL$10 -> 1 | R24: =AVERAGE(N24:Q24) -> 0.25446429 | T24: =T10/$AL$10 -> 0 | U24: =U10/$AL$10 -> 0 | V24: =V10/$AL$10 -> 0 | W24: =W10/$AL$10 -> 1.0178571 | X24: =AVERAGE(T24:W24) -> 0.25446429 | Z24: =Z10/$AL$10 -> 0 | AA24: =AA10/$AL$10 -> 0 | AB24: =AB10/$AL$10 -> 0.053571429 | AC24: =AC10/$AL$10 -> 0.96428571 | AD24: =AVERAGE(Z24:AC24) -> 0.25446429 | AG24: =AG10/$AL$10 -> 0 | AH24: =AH10/$AL$10 -> 0 | AI24: =AI10/$AL$10 -> 0.017857143 | AJ24: =AJ10/$AL$10 -> 1 | AK24: =AVERAGE(AG24:AJ24) -> 0.25446429
A25: August | B25: =B11/C11 -> #REF! | C25: =C11/D11 -> #REF! | D25: =D11/E11 -> #REF! | E25: =E11/F11 -> #REF! | H25: =H11/I11 -> #REF! | I25: =I11/J11 -> #REF! | J25: =J11/K11 -> #REF! | K25: =K11/L11 -> #REF! | N25: =N11/$AL$11 -> #REF! | O25: =O11/$AL$11 -> #REF! | P25: =P11/$AL$11 -> #REF! | Q25: =Q11/$AL$11 -> #REF! | R25: =AVERAGE(N25:Q25) -> #REF! | T25: =T11/$AL$11 -> #REF! | U25: =U11/$AL$11 -> #REF! | V25: =V11/$AL$11 -> #REF! | W25: =W11/$AL$11 -> #REF! | X25: =AVERAGE(T25:W25) -> #REF! | Z25: =Z11/$AL$11 -> #REF! | AA25: =AA11/$AL$11 -> #REF! | AB25: =AB11/$AL$11 -> #REF! | AC25: =AC11/$AL$11 -> #REF! | AD25: =AVERAGE(Z25:AC25) -> #REF! | AG25: =AG11/$AL$11 -> #REF! | AH25: =AH11/$AL$11 -> #REF! | AI25: =AI11/$AL$11 -> #REF! | AJ25: =AJ11/$AL$11 -> #REF! | AK25: =AVERAGE(AG25:AJ25) -> #REF!
A26: September | B26: =B12/C12 -> #REF! | C26: =C12/D12 -> #REF! | D26: =D12/E12 -> #REF! | E26: =E12/F12 -> #REF! | H26: =H12/I12 -> #REF! | I26: =I12/J12 -> #REF! | J26: =J12/K12 -> #REF! | K26: =K12/L12 -> #REF! | N26: =N12/$AL$12 -> #REF! | O26: =O12/$AL$12 -> #REF! | P26: =P12/$AL$12 -> #REF! | Q26: =Q12/$AL$12 -> #REF! | R26: =AVERAGE(N26:Q26) -> #REF! | T26: =T12/$AL$12 -> #REF! | U26: =U12/$AL$12 -> #REF! | V26: =V12/$AL$12 -> #REF! | W26: =W12/$AL$12 -> #REF! | X26: =AVERAGE(T26:W26) -> #REF! | Z26: =Z12/$AL$12 -> #REF! | AA26: =AA12/$AL$12 -> #REF! | AB26: =AB12/$AL$12 -> #REF! | AC26: =AC12/$AL$12 -> #REF! | AD26: =AVERAGE(Z26:AC26) -> #REF! | AG26: =AG12/$AL$12 -> #REF! | AH26: =AH12/$AL$12 -> #REF! | AI26: =AI12/$AL$12 -> #REF! | AJ26: =AJ12/$AL$12 -> #REF! | AK26: =AVERAGE(AG26:AJ26) -> #REF!
A27: October | B27: =B13/C13 -> #REF! | C27: =C13/D13 -> #REF! | D27: =D13/E13 -> #REF! | E27: =E13/F13 -> #REF! | H27: =H13/I13 -> #REF! | I27: =I13/J13 -> #REF! | J27: =J13/K13 -> #REF! | K27: =K13/L13 -> #REF! | N27: =N13/$AL$13 -> #REF! | O27: =O13/$AL$13 -> #REF! | P27: =P13/$AL$13 -> #REF! | Q27: =Q13/$AL$13 -> #REF! | R27: =AVERAGE(N27:Q27) -> #REF! | T27: =T13/$AL$13 -> #REF! | U27: =U13/$AL$13 -> #REF! | V27: =V13/$AL$13 -> #REF! | W27: =W13/$AL$13 -> #REF! | X27: =AVERAGE(T27:W27) -> #REF! | Z27: =Z13/$AL$13 -> #REF! | AA27: =AA13/$AL$13 -> #REF! | AB27: =AB13/$AL$13 -> #REF! | AC27: =AC13/$AL$13 -> #REF! | AD27: =AVERAGE(Z27:AC27) -> #REF! | AG27: =AG13/$AL$13 -> #REF! | AH27: =AH13/$AL$13 -> #REF! | AI27: =AI13/$AL$13 -> #REF! | AJ27: =AJ13/$AL$13 -> #REF! | AK27: =AVERAGE(AG27:AJ27) -> #REF!
A28: November
A29: December
B33: Service | C33: Food | D33: Activities | E33: Lodge Staff | F33: Accomodation | H33: Overall Stay
A34: Janaury
A35: February
A36: March
A37: April
A38: May | B38: =F22 -> 0 | C38: =L22 -> 0 | D38: =Q22 -> 1 | E38: =W22 -> 1 | F38: =AD22 -> 0.25 | H38: =AK22 -> 0.25
A39: June | B39: =F23 -> 0 | C39: =L23 -> 0 | D39: =Q23 -> 0.95744681 | E39: =W23 -> 1 | F39: =AD23 -> 0.25 | H39: =AK23 -> 0.25
A40: July | B40: =F24 -> 0 | C40: =L24 -> 0 | D40: =Q24 -> 1 | E40: =W24 -> 1.0178571 | F40: =AD24 -> 0.25446429 | H40: =AK24 -> 0.25446429
A41: August | B41: =F25 -> 0 | C41: =L25 -> 0 | D41: =Q25 -> #REF! | E41: =W25 -> #REF! | F41: =AD25 -> #REF! | H41: =AK25 -> #REF!
A42: September | B42: =F26 -> 0 | C42: =L26 -> 0 | D42: =Q26 -> #REF! | E42: =W26 -> #REF! | F42: =AD26 -> #REF! | H42: =AK26 -> #REF!
A43: October | B43: =F27 -> 0 | C43: =L27 -> 0 | D43: =Q27 -> #REF! | E43: =W27 -> #REF! | F43: =AD27 -> #REF! | H43: =AK27 -> #REF!
A44: November
A45: December
